<?xml version="1.0" ?>
<!-- =================================================================================== -->
<!-- |    This document was autogenerated by xacro from /home/iza/catkin_ws/src/es5_description/urdf/es5_with_franka.urdf.xacro | -->
<!-- |    EDITING THIS FILE BY HAND IS NOT RECOMMENDED                                 | -->
<!-- =================================================================================== -->
<robot name="es5_with_hand">
    <link name="sl_base">
        <visual>
            <origin rpy="0 0 0" xyz="0 0 0" />
            <geometry>
                <mesh filename="package://es5_description/meshes/sl_base.STL" />
            </geometry>
            <material name="">
                <color rgba="0.2 0.2 0.2 1" />
            </material>
        </visual>
        <collision>
            <origin rpy="0 0 0" xyz="0 0 0" />
            <geometry>
                <mesh filename="package://es5_description/meshes/sl_base.STL" />
            </geometry>
        </collision>
        <inertial>
            <mass value="0.1" />
            <origin xyz="0 0 0" rpy="0 0 0" />
            <inertia ixx="0.03" iyy="0.03" izz="0.03" ixy="0.0" ixz="0.0" iyz="0.0" />
        </inertial>
    </link>
    <link name="sl_1">
        <inertial>
            <origin rpy="0 0 0" xyz="-0.013237 -0.00054619 -0.014982" />
            <mass value="1.7688" />
            <inertia ixx="0.0016473" ixy="-1.3712E-05" ixz="0.00016089" iyy="0.0019378" iyz="2.4347E-05" izz="0.00036119" />
        </inertial>
        <visual>
            <origin rpy="0 0 0" xyz="0 0 0" />
            <geometry>
                <mesh filename="package://es5_description/meshes/sl_1.STL" />
            </geometry>
            <material name="">
                <color rgba="0.2 0.2 0.2 1" />
            </material>
        </visual>
        <collision>
            <origin rpy="0 0 0" xyz="0 0 0" />
            <geometry>
                <mesh filename="package://es5_description/meshes/sl_1.STL" />
            </geometry>
        </collision>
    </link>
    <joint name="ESJoint1" type="revolute">
        <origin rpy="0 0 3.1417" xyz="0 0 0.236" />
        <parent link="sl_base" />
        <child link="sl_1" />
        <axis xyz="0 0 1" />
        <limit effort="50" lower="-6.28" upper="6.28" velocity="5" />
    </joint>
    <link name="sl_2">
        <inertial>
            <origin rpy="0 0 0" xyz="0.015424 -9.646E-12 0.2125" />
            <mass value="6.7544" />
            <inertia ixx="0.19271" ixy="-1.9923E-12" ixz="2.1848E-10" iyy="0.19871" iyz="0.00035188" izz="0.0061413" />
        </inertial>
        <visual>
            <origin rpy="0 0 0" xyz="0 0 0" />
            <geometry>
                <mesh filename="package://es5_description/meshes/sl_2.STL" />
            </geometry>
            <material name="">
                <color rgba="0.2 0.2 0.2 1" />
            </material>
        </visual>
        <collision>
            <origin rpy="0 0 0" xyz="0 0 0" />
            <geometry>
                <mesh filename="package://es5_description/meshes/sl_2.STL" />
            </geometry>
        </collision>
    </link>
    <joint name="ESJoint2" type="revolute">
        <origin rpy="1.57 1.2147E-16 4.8192E-33" xyz="-0.147 0 0" />
        <parent link="sl_1" />
        <child link="sl_2" />
        <axis xyz="-1 0 0" />
        <limit effort="50" lower="-6.28" upper="6.28" velocity="5" />
    </joint>
    <link name="sl_3">
        <inertial>
            <origin rpy="0 0 0" xyz="-0.0091923 1.7292E-06 0.20596" />
            <mass value="2.3481" />
            <inertia ixx="0.047889" ixy="2.6294E-06" ixz="-0.00099127" iyy="0.04871" iyz="4.612E-05" izz="0.00084808" />
        </inertial>
        <visual>
            <origin rpy="0 0 0" xyz="0 0 0" />
            <geometry>
                <mesh filename="package://es5_description/meshes/sl_3.STL" />
            </geometry>
            <material name="">
                <color rgba="0.2 0.2 0.2 1" />
            </material>
        </visual>
        <collision>
            <origin rpy="0 0 0" xyz="0 0 0" />
            <geometry>
                <mesh filename="package://es5_description/meshes/sl_3.STL" />
            </geometry>
        </collision>
    </link>
    <joint name="ESJoint3" type="revolute">
        <origin rpy="1.6918E-15 2.2204E-16 2.9582E-31" xyz="0.1375 0 0.425" />
        <parent link="sl_2" />
        <child link="sl_3" />
        <axis xyz="-1 0 0" />
        <limit effort="50" lower="-6.28" upper="6.28" velocity="5" />
    </joint>
    <link name="sl_4">
        <inertial>
            <origin rpy="0 0 0" xyz="0.0036399 0.00019977 0.014282" />
            <mass value="0.56883" />
            <inertia ixx="0.00061834" ixy="2.969E-06" ixz="3.2084E-05" iyy="0.00064057" iyz="1.6935E-06" izz="4.0818E-05" />
        </inertial>
        <visual>
            <origin rpy="0 0 0" xyz="0 0 0" />
            <geometry>
                <mesh filename="package://es5_description/meshes/sl_4.STL" />
            </geometry>
            <material name="">
                <color rgba="0.2 0.2 0.2 1" />
            </material>
        </visual>
        <collision>
            <origin rpy="0 0 0" xyz="0 0 0" />
            <geometry>
                <mesh filename="package://es5_description/meshes/sl_4.STL" />
            </geometry>
        </collision>
    </link>
    <joint name="ESJoint4" type="revolute">
        <origin rpy="1.57 -5.388E-16 1.9374E-31" xyz="-0.101 0 0.395" />
        <parent link="sl_3" />
        <child link="sl_4" />
        <axis xyz="-1 0 0" />
        <limit effort="50" lower="-6.28" upper="6.28" velocity="5" />
    </joint>
    <link name="sl_5">
        <inertial>
            <origin rpy="0 0 0" xyz="-0.014282 -0.00019977 -0.0036399" />
            <mass value="0.56883" />
            <inertia ixx="4.0818E-05" ixy="1.6935E-06" ixz="3.2084E-05" iyy="0.00064057" iyz="2.969E-06" izz="0.00061834" />
        </inertial>
        <visual>
            <origin rpy="0 0 0" xyz="0 0 0" />
            <geometry>
                <mesh filename="package://es5_description/meshes/sl_5.STL" />
            </geometry>
            <material name="">
                <color rgba="0.2 0.2 0.2 1" />
            </material>
        </visual>
        <collision>
            <origin rpy="0 0 0" xyz="0 0 0" />
            <geometry>
                <mesh filename="package://es5_description/meshes/sl_5.STL" />
            </geometry>
        </collision>
    </link>
    <joint name="ESJoint5" type="revolute">
        <origin rpy="0 0 3.1417" xyz="0 0 0.101" />
        <parent link="sl_4" />
        <child link="sl_5" />
        <axis xyz="0 0 1" />
        <limit effort="50" lower="-6.28" upper="6.28" velocity="5" />
    </joint>
    <link name="sl_6">
        <inertial>
            <origin rpy="0 0 0" xyz="-0.064015 7.6673E-07 -0.00019082" />
            <mass value="0.17537" />
            <inertia ixx="1.3436E-06" ixy="1.5557E-11" ixz="-3.8717E-09" iyy="9.8324E-07" iyz="1.9341E-13" izz="9.8319E-07" />
        </inertial>
        <visual>
            <origin rpy="0 0 0" xyz="0 0 0" />
            <geometry>
                <mesh filename="package://es5_description/meshes/sl_6.STL" />
            </geometry>
            <material name="">
                <color rgba="0.2 0.2 0.2 1" />
            </material>
        </visual>
        <collision>
            <origin rpy="0 0 0" xyz="0 0 0" />
            <geometry>
                <mesh filename="package://es5_description/meshes/sl_6.STL" />
            </geometry>
        </collision>
    </link>
    <joint name="ESJoint6" type="revolute">
        <origin rpy="0 0 0" xyz="0 0 0" />
        <parent link="sl_5" />
        <child link="sl_6" />
        <axis xyz="1 0 0" />
        <limit effort="50" lower="-6.28" upper="6.28" velocity="5" />
    </joint>
    <joint name="_hand_joint" type="fixed">
        <parent link="sl_6" />
        <child link="_hand" />
        <origin rpy="0 -1.5707963267948966 0" xyz="-0.075 0 0" />
    </joint>
    <link name="_hand">
        <visual>
            <origin rpy="0 0 0" xyz="0 0 0" />
            <geometry>
                <mesh filename="package://franka_description/meshes/hand.STL" />
            </geometry>
            <material name="">
                <color rgba="1 1 1 1" />
            </material>
        </visual>
        <collision>
            <origin rpy="0 0 0" xyz="0 0 0" />
            <geometry>
                <mesh filename="package://franka_description/meshes/hand_collision.STL" />
            </geometry>
        </collision>
        <inertial>
            <mass value="0.1" />
            <origin xyz="0 0 0" rpy="0 0 0" />
            <inertia ixx="0.03" iyy="0.03" izz="0.03" ixy="0.0" ixz="0.0" iyz="0.0" />
        </inertial>
    </link>
    <link name="_leftfinger">
        <visual>
            <origin rpy="0 0 0" xyz="0 0 0" />
            <geometry>
                <mesh filename="package://franka_description/meshes/leftfinger.STL" />
            </geometry>
            <material name="">
                <color rgba="1 1 1 1" />
            </material>
        </visual>
        <collision>
            <geometry>
                <mesh filename="package://franka_description/meshes/leftfinger_collision.STL" />
            </geometry>
        </collision>
        <inertial>
            <mass value="0.1" />
            <origin xyz="0 0 0" rpy="0 0 0" />
            <inertia ixx="0.03" iyy="0.03" izz="0.03" ixy="0.0" ixz="0.0" iyz="0.0" />
        </inertial>
    </link>
    <link name="_rightfinger">
        <visual>
            <origin rpy="0 0 0" xyz="0 0 0" />
            <geometry>
                <mesh filename="package://franka_description/meshes/rightfinger.STL" />
            </geometry>
            <material name="">
                <color rgba="1 1 1 1" />
            </material>
        </visual>
        <collision>
            <geometry>
                <mesh filename="package://franka_description/meshes/rightfinger_collision.STL" />
            </geometry>
        </collision>
        <inertial>
            <mass value="0.1" />
            <origin xyz="0 0 0" rpy="0 0 0" />
            <inertia ixx="0.03" iyy="0.03" izz="0.03" ixy="0.0" ixz="0.0" iyz="0.0" />
        </inertial>
    </link>
    <joint name="_finger_joint1" type="prismatic">
        <parent link="_hand" />
        <child link="_leftfinger" />
        <origin rpy="0 0 0" xyz="0 0 0.0584" />
        <axis xyz="0 1 0" />
        <limit effort="20" lower="-0.001" upper="0.04" velocity="0.3" />
    </joint>
    <joint name="_finger_joint2" type="prismatic">
        <parent link="_hand" />
        <child link="_rightfinger" />
        <origin rpy="0 0 0" xyz="0 0 0.0584" />
        <axis xyz="0 -1 0" />
        <limit effort="20" lower="-0.001" upper="0.04" velocity="0.3" />
    </joint>
    <transmission name="trans_ESJoint1">
        <type>transmission_interface/SimpleTransmission</type>
        <joint name="ESJoint1">
            <hardwareInterface>hardware_interface/PositionJointInterface</hardwareInterface>
        </joint>
        <actuator name="ESJoint1_motor">
            <hardwareInterface>hardware_interface/PositionJointInterface</hardwareInterface>
            <mechanicalReduction>1</mechanicalReduction>
        </actuator>
    </transmission>
    <transmission name="trans_ESJoint2">
        <type>transmission_interface/SimpleTransmission</type>
        <joint name="ESJoint2">
            <hardwareInterface>hardware_interface/PositionJointInterface</hardwareInterface>
        </joint>
        <actuator name="ESJoint2_motor">
            <hardwareInterface>hardware_interface/PositionJointInterface</hardwareInterface>
            <mechanicalReduction>1</mechanicalReduction>
        </actuator>
    </transmission>
    <transmission name="trans_ESJoint3">
        <type>transmission_interface/SimpleTransmission</type>
        <joint name="ESJoint3">
            <hardwareInterface>hardware_interface/PositionJointInterface</hardwareInterface>
        </joint>
        <actuator name="ESJoint3_motor">
            <hardwareInterface>hardware_interface/PositionJointInterface</hardwareInterface>
            <mechanicalReduction>1</mechanicalReduction>
        </actuator>
    </transmission>
    <transmission name="trans_ESJoint4">
        <type>transmission_interface/SimpleTransmission</type>
        <joint name="ESJoint4">
            <hardwareInterface>hardware_interface/PositionJointInterface</hardwareInterface>
        </joint>
        <actuator name="ESJoint4_motor">
            <hardwareInterface>hardware_interface/PositionJointInterface</hardwareInterface>
            <mechanicalReduction>1</mechanicalReduction>
        </actuator>
    </transmission>
    <transmission name="trans_ESJoint5">
        <type>transmission_interface/SimpleTransmission</type>
        <joint name="ESJoint5">
            <hardwareInterface>hardware_interface/PositionJointInterface</hardwareInterface>
        </joint>
        <actuator name="ESJoint5_motor">
            <hardwareInterface>hardware_interface/PositionJointInterface</hardwareInterface>
            <mechanicalReduction>1</mechanicalReduction>
        </actuator>
    </transmission>
    <transmission name="trans_ESJoint6">
        <type>transmission_interface/SimpleTransmission</type>
        <joint name="ESJoint6">
            <hardwareInterface>hardware_interface/PositionJointInterface</hardwareInterface>
        </joint>
        <actuator name="ESJoint6_motor">
            <hardwareInterface>hardware_interface/PositionJointInterface</hardwareInterface>
            <mechanicalReduction>1</mechanicalReduction>
        </actuator>
    </transmission>
    <transmission name="trans__finger_joint1">
        <type>transmission_interface/SimpleTransmission</type>
        <joint name="_finger_joint1">
            <hardwareInterface>hardware_interface/PositionJointInterface</hardwareInterface>
        </joint>
        <actuator name="_finger_joint1_motor">
            <hardwareInterface>hardware_interface/PositionJointInterface</hardwareInterface>
            <mechanicalReduction>1</mechanicalReduction>
        </actuator>
    </transmission>
    <transmission name="trans__finger_joint2">
        <type>transmission_interface/SimpleTransmission</type>
        <joint name="_finger_joint2">
            <hardwareInterface>hardware_interface/PositionJointInterface</hardwareInterface>
        </joint>
        <actuator name="_finger_joint2_motor">
            <hardwareInterface>hardware_interface/PositionJointInterface</hardwareInterface>
            <mechanicalReduction>1</mechanicalReduction>
        </actuator>
    </transmission>
  <gazebo>
  <plugin name="gazebo_ros_control" filename="libgazebo_ros_control.so">
  <robotNamespace>/</robotNamespace>
  </plugin>
  </gazebo>
</robot>



